<mujoco model="ant">
  <compiler angle="degree" coordinate="local" inertiafromgeom="true"/>
  <option integrator="RK4" timestep="0.002"/>
  <custom>
    <numeric data="0.0 0.0 0.55 1.0 0.0 0.0 0.0 0.0 1.0 0.0 -1.0 0.0 -1.0 0.0 1.0" name="init_qpos"/>
  </custom>
  <default>
    <joint armature="1" damping="1" limited="true"/>
    <geom conaffinity="0" condim="3" density="5.0" friction="1 0.5 0.5" margin="0.01" rgba="0.8 0.6 0.4 1"/>
  </default>
  <asset>
    <texture builtin="gradient" height="100" rgb1="1 1 1" rgb2="0 0 0" type="skybox" width="100"/>
    <texture builtin="flat" height="1278" mark="cross" markrgb="1 1 1" name="texgeom" random="0.01" rgb1="0.8 0.6 0.4" rgb2="0.8 0.6 0.4" type="cube" width="127"/>
    <texture builtin="checker" height="100" name="texplane" rgb1="0 0 0" rgb2="0.8 0.8 0.8" type="2d" width="100"/>
    <material name="MatPlane" reflectance="0.5" shininess="1" specular="1" texrepeat="60 60" texture="texplane"/>
    <material name="geom" texture="texgeom" texuniform="true"/>
  </asset>
  <worldbody>
    <light cutoff="100" diffuse="1 1 1" dir="-0 0 -1.3" directional="true" exponent="1" pos="0 0 1.3" specular=".1 .1 .1"/>
    <geom conaffinity="1" condim="6" material="MatPlane" name="floor" pos="0 0 0" rgba="0.8 0.9 0.8 1" size="40 40 40"  type="plane"/>
    <body pos="0 0 0.75">

      <!--몸통-->
      <geom name="torso" fromto ="-0.4 0.0 0.0 0.2 0.0 0.0" size="0.12" type="capsule"/>
      <!--<geom name="torso_geom2" pos ="0 0 0" size="0.2" type="sphere"/>-->

      <!--머리-->
      <geom name="head" pos ="0.4 0 0" size="0.23" type="sphere"/>
      <!--<joint axis="0 0 1" name="head_1" pos="0.0 0.0 0.0" range="-10 10" type="hinge"/>
				<joint axis="0 1 0" name="head_2" pos="0.0 0.0 0.0" range="-10 10" type="hinge"/>-->

      <!--<body name="feeler" pos="0.5 0 0">
					<geom name="feeler" fromto ="0 0.0 0 0.4 0.4 0" size="0.02" type="capsule"/>-->

      <!--배-->
      <geom name="tail" fromto ="-1.0 0 0 -0.6 0 0.0" size="0.2" type="capsule"/>
      <!--<joint axis="0 0 1" name="tail_1" pos="0.0 0.0 0.0" range="-20 20" type="hinge"/>
				<joint axis="0 1 0" name="tail_2" pos="0.0 0.0 0.0" range="-10 10" type="hinge"/>-->

      <!--배-->
      <!--<geom name="connected" fromto ="-0.6 0.0 0 -0.5 0.0 0.0" size="0.05" type="capsule"/>-->
      <!--<body name="tail" pos="-0.6 0 0">
				<geom name="tail" fromto ="-0.6 0 0 -0.2 0 0.0" size="0.12" type="capsule"/>
				<joint axis="0 0 1" name="tail_1" pos="0.0 0.0 0.0" range="-20 20" type="hinge"/>
				<joint axis="0 1 0" name="tail_2" pos="0.0 0.0 0.0" range="-10 10" type="hinge"/>
			</body>-->

      <joint armature="0" damping="0" limited="false" margin="0.01" name="root" pos="0 0 0" type="free"/>

      <!--다리1-->
      <body pos="0.15 0.2 0">
        <geom fromto="0.0 0.0 0.0 0.2 0.2 0.0" name="aux_left_forward" size="0.1" type="capsule"/>
        <body pos="0.2 0.2 0">
          <joint axis="0 0 1" name="joint_leg_left_forward" pos="0.0 0.0 0.0" range="-30 30" type="hinge"/>
          <!--<joint axis="1 0 0" name="hip_1x" pos="0.0 0.0 0.0" range="-5 5" type="hinge"/>-->
          <geom fromto="0.0 0.0 0.0 0.2 0.2 0.0" name="leg_left_forward" size="0.09" type="capsule"/>
          <body pos="0.2 0.2 0">
            <joint axis="-1 1 0" name="joint_ankle_left_forward" pos="0.0 0.0 0.0" range="30 70" type="hinge"/>
            <geom fromto="0.0 0.0 0.0 0.4 0.4 0.0" name="ankle_left_forward" size="0.08" type="capsule"/>
          </body>
        </body>
      </body>

      <!--다리2-->
      <body pos="-0.075 0.2 0">
        <geom fromto="0.0 0.0 0.0 0.0 0.28284 0.0" name="aux_left_middle" size="0.1" type="capsule"/>
        <body pos="0.0 0.28284 0">
          <joint axis="0 0 1" name="joint_leg_left_middle" pos="0.0 0 0.0" range="-30 30" type="hinge"/>
          <!--<joint axis="1 0 0" name="hip_2x" pos="0.0 0.0 0.0" range="-5 5" type="hinge"/>-->
          <geom fromto="0.0 0.0 0.0 0.0 0.28284 0.0" name="leg_left_middle" size="0.09" type="capsule"/>
          <body pos="0.0 0.28284 0">
            <joint axis="-1 0 0" name="joint_ankle_left_middle" pos="0.0 0 0.0" range="30 70" type="hinge"/>
            <geom fromto="0.0 0.56568 0.0 0 0 0.0" name="ankle_left_middle" size="0.08" type="capsule"/>
          </body>
        </body>
      </body>

      <!--다리3-->
      <body pos="-0.3 0.1 0">
        <geom fromto="0.0 0.0 0.0 -0.2 0.2 0.0" name="aux_left_backward" size="0.1" type="capsule"/>
        <body pos="-0.2 0.2 0">
          <joint axis="0 0 1" name="joint_leg_left_backward" pos="0.0 0.0 0.0" range="-30 30" type="hinge"/>
          <!--<joint axis="1 0 0" name="hip_3x" pos="0.0 0.0 0.0" range="-5 5" type="hinge"/>-->
          <geom fromto="0.0 0.0 0.0 -0.2 0.2 0.0" name="leg_left_backward" size="0.09" type="capsule"/>
          <body pos="-0.2 0.2 0">
            <joint axis="-1 -1 0" name="joint_ankle_left_backward" pos="0.0 0.0 0.0" range="30 70" type="hinge"/>
            <geom fromto="0.0 0.0 0.0 -0.4 0.4 0.0" name="ankle_left_backward" size="0.08" type="capsule"/>
          </body>
        </body>
      </body>

      <!--다리 4-->
      <body pos="0.15 -0.2 0">
        <geom fromto="0.0 0.0 0.0 0.2 -0.2 0.0" name="aux_right_forward" size="0.1" type="capsule"/>
        <body pos="0.2 -0.2 0">
          <joint axis="0 0 -1" name="joint_leg_right_forward" pos="0.0 0.0 0.0" range="-30 30" type="hinge"/>
          <!--<joint axis="1 0 0" name="hip_6x" pos="0.0 0.0 0.0" range="-5 5" type="hinge"/>-->
          <geom fromto="0.0 0.0 0.0 0.2 -0.2 0.0" name="leg_right_forward" size="0.09" type="capsule"/>
          <body pos="0.2 -0.2 0">
            <joint axis="1 1 0" name="joint_ankle_right_forward" pos="0.0 0.0 0.0" range="30 70" type="hinge"/>
            <geom fromto="0.0 0.0 0.0 0.4 -0.4 0.0" name="ankle_right_forward" size="0.08" type="capsule"/>
          </body>
        </body>
      </body>
      
      <!--다리 5-->
      <body pos="-0.075 -0.2 0">
        <geom fromto="0.0 0 0.0 0 -0.28284 0.0" name="aux_right_middle" size="0.1" type="capsule"/>
        <body pos="0 -0.28284 0">
          <joint axis="0 0 -1" name="joint_leg_right_middle" pos="0.0 0.0 0.0" range="-30 30" type="hinge"/>
          <!--<joint axis="1 0 0" name="hip_5x" pos="0.0 0.0 0.0" range="-5 5" type="hinge"/>-->
          <geom fromto="0.0 0 0.0 0 -0.28284 0.0" name="leg_right_middle" size="0.09" type="capsule"/>
          <body pos="0 -0.28284 0">
            <joint axis="1 0 0" name="joint_ankle_right_middle" pos="0.0 0.0 0.0" range="30 70" type="hinge"/>
            <geom fromto="0.0 -0.56568 0.0 0 0 0.0" name="ankle_right_middle" size="0.08" type="capsule"/>
          </body>
        </body>
      </body>

      <!--다리6-->
      <body pos="-0.3 -0.1 0">
        <geom fromto="0.0 0.0 0.0 -0.2 -0.2 0.0" name="aux_right_backward" size="0.1" type="capsule"/>
        <body pos="-0.2 -0.2 0">
          <joint axis="0 0 -1" name="joint_leg_right_backward" pos="0.0 0.0 0.0" range="-30 30" type="hinge"/>
          <!--<joint axis="1 0 0" name="hip_4x" pos="0.0 0.0 0.0" range="-5 5" type="hinge"/>-->
          <geom fromto="0.0 0.0 0.0 -0.2 -0.2 0.0" name="leg_right_backward" size="0.09" type="capsule"/>
          <body pos="-0.2 -0.2 0">
            <joint axis="1 -1 0" name="joint_ankle_right_backward" pos="0.0 0.0 0.0" range="30 70" type="hinge"/>
            <geom fromto="0.0 0.0 0.0 -0.4 -0.4 0.0" name="ankle_right_backward" size="0.08" type="capsule"/>
          </body>
        </body>
      </body>
      
    </body>
  </worldbody>

  <actuator>

    <motor ctrllimited="true" ctrlrange="-1.0 1.0" joint="joint_leg_left_forward" gear="301"/>
    <!--<motor ctrllimited="true" ctrlrange="-1.0 1.0" joint="hip_1x" gear="50"/>-->
    <motor ctrllimited="true" ctrlrange="-1.00 1.00" joint="joint_ankle_left_forward" gear="100"/>

    <motor ctrllimited="true" ctrlrange="-1.0 1.0" joint="joint_leg_left_middle" gear="301"/>
    <!--<motor ctrllimited="true" ctrlrange="-1.0 1.0" joint="hip_2x" gear="50"/>-->
    <motor ctrllimited="true" ctrlrange="-1.00 1.00" joint="joint_ankle_left_middle" gear="100"/>

    <motor ctrllimited="true" ctrlrange="-1.0 1.0" joint="joint_leg_left_backward" gear="301"/>
    <!--<motor ctrllimited="true" ctrlrange="-1.0 1.0" joint="hip_3x" gear="301"/>-->
    <motor ctrllimited="true" ctrlrange="-1.00 1.00" joint="joint_ankle_left_forward" gear="100"/>

    <motor ctrllimited="true" ctrlrange="-1.0 1.0" joint="joint_leg_right_forward" gear="301"/>
    <!--<motor ctrllimited="true" ctrlrange="-1.0 1.0" joint="hip_6x" gear="301"/>-->
    <motor ctrllimited="true" ctrlrange="-1.00 1.00" joint="joint_ankle_right_forward" gear="100"/>

    <motor ctrllimited="true" ctrlrange="-1.0 1.0" joint="joint_leg_right_middle" gear="301"/>
    <!--<motor ctrllimited="true" ctrlrange="-1.0 1.0" joint="hip_5x" gear="301"/>-->
    <motor ctrllimited="true" ctrlrange="-1.00 1.00" joint="joint_ankle_right_middle" gear="100"/>

    <motor ctrllimited="true" ctrlrange="-1.0 1.0" joint="joint_leg_right_backward" gear="301"/>
    <!--<motor ctrllimited="true" ctrlrange="-1.0 1.0" joint="hip_4x" gear="301"/>-->
    <motor ctrllimited="true" ctrlrange="-1.00 1.00" joint="joint_ankle_right_backward" gear="100"/>

    <!--<motor ctrllimited="true" ctrlrange="-1.0 1.0" joint="head_1" gear="150"/>
		<motor ctrllimited="true" ctrlrange="-1.0 1.0" joint="head_2" gear="150"/>
		<motor ctrllimited="true" ctrlrange="-1.0 1.0" joint="tail_1" gear="150"/>
		<motor ctrllimited="true" ctrlrange="-1.0 1.0" joint="tail_2" gear="150"/>-->
  </actuator>

  <!--<sensor>
		<touch name="touch_first_ankle_geom" site="first_ankle_geom"/>
		<touch name="touch_second_ankle_geom" site="second_ankle_geom"/>
		<touch name="touch_third_ankle_geom" site="third_ankle_geom"/>
		<touch name="touch_sixth_ankle_geom" site="sixth_ankle_geom"/>
		<touch name="touch_fourth_ankle_geom" site="seventh_ankle_geom"/>
		<touch name="touch_fifth_ankle_geom" site="eighth_ankle_geom"/>
	</sensor>-->

</mujoco>
